<?xml version="1.0" encoding="utf-8"?>
<!-- This URDF was automatically created by SolidWorks to URDF Exporter! Originally created by Stephen Brawner (brawner@gmail.com) 
     Commit Version: 1.6.0-1-g15f4949  Build Version: 1.6.7594.29634
     For more information, please see http://wiki.ros.org/sw_urdf_exporter -->
<robot
  name="physio">
  <link
    name="base_link">
    <inertial>
      <origin
        xyz="0.24199 -0.24703 0.48152"
        rpy="0 0 0" />
      <mass
        value="8.9953" />
      <inertia
        ixx="0.75382"
        ixy="0.0012961"
        ixz="0.31647"
        iyy="0.97956"
        iyz="-0.019777"
        izz="0.64235" />
    </inertial>
    <visual>
      <origin
        xyz="0 0 0"
        rpy="0 0 0" />
      <geometry>
        <mesh
          filename="package://physio/meshes/base_link.STL" />
      </geometry>
      <material
        name="">
        <color
          rgba="0.25098 0.25098 0.25098 1" />
      </material>
    </visual>
    <collision>
      <origin
        xyz="0 0 0"
        rpy="0 0 0" />
      <geometry>
        <mesh
          filename="package://physio/meshes/base_link.STL" />
      </geometry>
    </collision>
  </link>
  <link
    name="arm1">
    <inertial>
      <origin
        xyz="0.14147 0.0034965 0.025666"
        rpy="0 0 0" />
      <mass
        value="0.09284" />
      <inertia
        ixx="1.4217E-05"
        ixy="1.069E-05"
        ixz="6.0916E-07"
        iyy="0.00068892"
        iyz="-2.7338E-07"
        izz="0.00068752" />
    </inertial>
    <visual>
      <origin
        xyz="0 0 0"
        rpy="0 0 0" />
      <geometry>
        <mesh
          filename="package://physio/meshes/arm1.STL" />
      </geometry>
      <material
        name="">
        <color
          rgba="0.79216 0.81961 0.93333 1" />
      </material>
    </visual>
    <collision>
      <origin
        xyz="0 0 0"
        rpy="0 0 0" />
      <geometry>
        <mesh
          filename="package://physio/meshes/arm1.STL" />
      </geometry>
    </collision>
  </link>
  <joint
    name="joint1"
    type="revolute">
    <origin
      xyz="0.005 -0.492 0.995"
      rpy="1.5708 0.76627 0" />
    <parent
      link="base_link" />
    <child
      link="arm1" />
    <axis
      xyz="0 0 1" />
    <limit
      lower="-0.785"
      upper="0.785"
      effort="0"
      velocity="0" />
  </joint>
  <link
    name="arm2">
    <inertial>
      <origin
        xyz="0.14613 -0.01013 0.017903"
        rpy="0 0 0" />
      <mass
        value="0.1248" />
      <inertia
        ixx="1.8239E-05"
        ixy="5.9972E-06"
        ixz="-1.7615E-06"
        iyy="0.00099286"
        iyz="1.2212E-07"
        izz="0.00097766" />
    </inertial>
    <visual>
      <origin
        xyz="0 0 0"
        rpy="0 0 0" />
      <geometry>
        <mesh
          filename="package://physio/meshes/arm2.STL" />
      </geometry>
      <material
        name="">
        <color
          rgba="0.79216 0.81961 0.93333 1" />
      </material>
    </visual>
    <collision>
      <origin
        xyz="0 0 0"
        rpy="0 0 0" />
      <geometry>
        <mesh
          filename="package://physio/meshes/arm2.STL" />
      </geometry>
    </collision>
  </link>
  <joint
    name="joint2"
    type="revolute">
    <origin
      xyz="0.29 0.01 0"
      rpy="0 0 0.76627" />
    <parent
      link="arm1" />
    <child
      link="arm2" />
    <axis
      xyz="0 0 1" />
    <limit
      lower="-0.785"
      upper="0.785"
      effort="0"
      velocity="0" />
  </joint>
</robot>